[32m2023-07-03 19:27:08 +0530[0m - dagster - [34mDEBUG[0m - contract_job - 5c05aba9-1205-47fc-af14-5dae60347391 - 364633 - LOGS_CAPTURED - Started capturing logs in process (pid: 364633).
[32m2023-07-03 19:27:08 +0530[0m - dagster - [34mDEBUG[0m - contract_job - 5c05aba9-1205-47fc-af14-5dae60347391 - 364633 - contract_api_assets - STEP_START - Started execution of step "contract_api_assets".
[32m2023-07-03 19:27:08 +0530[0m - dagster - [34mERROR[0m - [31mcontract_job - 5c05aba9-1205-47fc-af14-5dae60347391 - 364633 - contract_api_assets - STEP_FAILURE - Execution of step "contract_api_assets" failed.

dagster._core.errors.DagsterExecutionStepExecutionError: Error occurred while executing op "contract_api_assets"::

requests.exceptions.ConnectionError: HTTPSConnectionPool(host='api.etherscan.io', port=443): Max retries exceeded with url: /api?module=contract&action=getsourcecode&address=ADDRESS&apikey=M2Z69469HXICTNG2WJC9BC6IWECE3QY2K7 (Caused by NewConnectionError('<urllib3.connection.HTTPSConnection object at 0x7f78871fff10>: Failed to establish a new connection: [Errno -3] Temporary failure in name resolution'))

Stack Trace:
  File "/home/mansi-bhatt/dagster/venv/lib/python3.11/site-packages/dagster/_core/execution/plan/utils.py", line 54, in op_execution_error_boundary
    yield
  File "/home/mansi-bhatt/dagster/venv/lib/python3.11/site-packages/dagster/_utils/__init__.py", line 445, in iterate_with_context
    next_output = next(iterator)
                  ^^^^^^^^^^^^^^
  File "/home/mansi-bhatt/dagster/venv/lib/python3.11/site-packages/dagster/_core/execution/plan/compute_generator.py", line 124, in _coerce_op_compute_fn_to_iterator
    result = invoke_compute_fn(
             ^^^^^^^^^^^^^^^^^^
  File "/home/mansi-bhatt/dagster/venv/lib/python3.11/site-packages/dagster/_core/execution/plan/compute_generator.py", line 118, in invoke_compute_fn
    return fn(context, **args_to_pass) if context_arg_provided else fn(**args_to_pass)
                                                                    ^^^^^^^^^^^^^^^^^^
  File "/home/mansi-bhatt/dagster/fetch-csv-project/fetch_csv_project/assets.py", line 28, in contract_api_assets
    api = fetch_api(contract_address)
          ^^^^^^^^^^^^^^^^^^^^^^^^^^^
  File "/home/mansi-bhatt/dagster/fetch-csv-project/fetch_csv_project/assets.py", line 13, in fetch_api
    r = requests.get(url)
        ^^^^^^^^^^^^^^^^^
  File "/home/mansi-bhatt/dagster/venv/lib/python3.11/site-packages/requests/api.py", line 73, in get
    return request("get", url, params=params, **kwargs)
           ^^^^^^^^^^^^^^^^^^^^^^^^^^^^^^^^^^^^^^^^^^^^
  File "/home/mansi-bhatt/dagster/venv/lib/python3.11/site-packages/requests/api.py", line 59, in request
    return session.request(method=method, url=url, **kwargs)
           ^^^^^^^^^^^^^^^^^^^^^^^^^^^^^^^^^^^^^^^^^^^^^^^^^
  File "/home/mansi-bhatt/dagster/venv/lib/python3.11/site-packages/requests/sessions.py", line 589, in request
    resp = self.send(prep, **send_kwargs)
           ^^^^^^^^^^^^^^^^^^^^^^^^^^^^^^
  File "/home/mansi-bhatt/dagster/venv/lib/python3.11/site-packages/requests/sessions.py", line 703, in send
    r = adapter.send(request, **kwargs)
        ^^^^^^^^^^^^^^^^^^^^^^^^^^^^^^^
  File "/home/mansi-bhatt/dagster/venv/lib/python3.11/site-packages/requests/adapters.py", line 519, in send
    raise ConnectionError(e, request=request)

The above exception occurred during handling of the following exception:
urllib3.exceptions.MaxRetryError: HTTPSConnectionPool(host='api.etherscan.io', port=443): Max retries exceeded with url: /api?module=contract&action=getsourcecode&address=ADDRESS&apikey=M2Z69469HXICTNG2WJC9BC6IWECE3QY2K7 (Caused by NewConnectionError('<urllib3.connection.HTTPSConnection object at 0x7f78871fff10>: Failed to establish a new connection: [Errno -3] Temporary failure in name resolution'))

Stack Trace:
  File "/home/mansi-bhatt/dagster/venv/lib/python3.11/site-packages/requests/adapters.py", line 486, in send
    resp = conn.urlopen(
           ^^^^^^^^^^^^^
  File "/home/mansi-bhatt/dagster/venv/lib/python3.11/site-packages/urllib3/connectionpool.py", line 798, in urlopen
    retries = retries.increment(
              ^^^^^^^^^^^^^^^^^^
  File "/home/mansi-bhatt/dagster/venv/lib/python3.11/site-packages/urllib3/util/retry.py", line 592, in increment
    raise MaxRetryError(_pool, url, error or ResponseError(cause))

The above exception occurred during handling of the following exception:
urllib3.exceptions.NewConnectionError: <urllib3.connection.HTTPSConnection object at 0x7f78871fff10>: Failed to establish a new connection: [Errno -3] Temporary failure in name resolution

Stack Trace:
  File "/home/mansi-bhatt/dagster/venv/lib/python3.11/site-packages/urllib3/connectionpool.py", line 714, in urlopen
    httplib_response = self._make_request(
                       ^^^^^^^^^^^^^^^^^^^
  File "/home/mansi-bhatt/dagster/venv/lib/python3.11/site-packages/urllib3/connectionpool.py", line 403, in _make_request
    self._validate_conn(conn)
  File "/home/mansi-bhatt/dagster/venv/lib/python3.11/site-packages/urllib3/connectionpool.py", line 1053, in _validate_conn
    conn.connect()
  File "/home/mansi-bhatt/dagster/venv/lib/python3.11/site-packages/urllib3/connection.py", line 363, in connect
    self.sock = conn = self._new_conn()
                       ^^^^^^^^^^^^^^^^
  File "/home/mansi-bhatt/dagster/venv/lib/python3.11/site-packages/urllib3/connection.py", line 186, in _new_conn
    raise NewConnectionError(

The above exception occurred during handling of the following exception:
socket.gaierror: [Errno -3] Temporary failure in name resolution

Stack Trace:
  File "/home/mansi-bhatt/dagster/venv/lib/python3.11/site-packages/urllib3/connection.py", line 174, in _new_conn
    conn = connection.create_connection(
           ^^^^^^^^^^^^^^^^^^^^^^^^^^^^^
  File "/home/mansi-bhatt/dagster/venv/lib/python3.11/site-packages/urllib3/util/connection.py", line 72, in create_connection
    for res in socket.getaddrinfo(host, port, family, socket.SOCK_STREAM):
               ^^^^^^^^^^^^^^^^^^^^^^^^^^^^^^^^^^^^^^^^^^^^^^^^^^^^^^^^^^
  File "/usr/lib/python3.11/socket.py", line 962, in getaddrinfo
    for res in _socket.getaddrinfo(host, port, family, type, proto, flags):
               ^^^^^^^^^^^^^^^^^^^^^^^^^^^^^^^^^^^^^^^^^^^^^^^^^^^^^^^^^^^
[0m
